Traceback (most recent call last):
  File "c:\users\user01\anaconda3\envs\dcn2\lib\site-packages\jupyter_cache\executors\utils.py", line 56, in single_nb_execution
    record_timing=False,
  File "c:\users\user01\anaconda3\envs\dcn2\lib\site-packages\nbclient\client.py", line 1087, in execute
    return NotebookClient(nb=nb, resources=resources, km=km, **kwargs).execute()
  File "c:\users\user01\anaconda3\envs\dcn2\lib\site-packages\nbclient\util.py", line 74, in wrapped
    return just_run(coro(*args, **kwargs))
  File "c:\users\user01\anaconda3\envs\dcn2\lib\site-packages\nbclient\util.py", line 53, in just_run
    return loop.run_until_complete(coro)
  File "c:\users\user01\anaconda3\envs\dcn2\lib\asyncio\base_events.py", line 568, in run_until_complete
    return future.result()
  File "c:\users\user01\anaconda3\envs\dcn2\lib\site-packages\nbclient\client.py", line 541, in async_execute
    cell, index, execution_count=self.code_cells_executed + 1
  File "c:\users\user01\anaconda3\envs\dcn2\lib\site-packages\nbclient\client.py", line 832, in async_execute_cell
    self._check_raise_for_error(cell, exec_reply)
  File "c:\users\user01\anaconda3\envs\dcn2\lib\site-packages\nbclient\client.py", line 740, in _check_raise_for_error
    raise CellExecutionError.from_cell_and_msg(cell, exec_reply['content'])
nbclient.exceptions.CellExecutionError: An error occurred while executing the following cell:
------------------
# Your status:
status = json_response["Data"]
#print(json.dumps(json_response, indent=4))

#request status (Running, Error, Finished)
request_status = json_response["Data"]["AsyncStatus"]

if request_status == "Running":
    print ("Your request is runnig check the status again in a few seconds...")
if request_status == "Error":
    print ("Your request has finished with the following errors:")
    error_list=json_response["Data"]["ErrorList"]
    print(error_list)
    print ("Correct the errros and sublit the document again")
elif request_status == "Finished":
    print ("Your request has finished.")
    outbound_financial_document_id = json_response["Data"]["OutboundFinancialDocumentId"]
    print("You have created the outbound document id: " + outbound_financial_document_id)
else:
    print("Your request status: " + request_status);

#print(json_response["Data"]["ErrorList"])
print(outbound_financial_document_id)
------------------

[1;31m---------------------------------------------------------------------------[0m
[1;31mNameError[0m                                 Traceback (most recent call last)
[1;32m<ipython-input-12-10c48290fac8>[0m in [0;36m<module>[1;34m[0m
[0;32m     21[0m [1;33m[0m[0m
[0;32m     22[0m [1;31m#print(json_response["Data"]["ErrorList"])[0m[1;33m[0m[1;33m[0m[0m
[1;32m---> 23[1;33m [0mprint[0m[1;33m([0m[0moutbound_financial_document_id[0m[1;33m)[0m[1;33m[0m[0m
[0m
[1;31mNameError[0m: name 'outbound_financial_document_id' is not defined
NameError: name 'outbound_financial_document_id' is not defined

